<?xml version="1.0" encoding="utf-8"?>
<!-- This URDF was automatically created by SolidWorks to URDF Exporter! Originally created by Stephen Brawner (brawner@gmail.com) 
     Commit Version: 1.6.0-4-g7f85cfe  Build Version: 1.6.7995.38578
     For more information, please see http://wiki.ros.org/sw_urdf_exporter -->
<robot
  name="robot_arm_simulation">
  <mujoco>
    <compiler meshdir="../meshes/" balanceinertia="true" discardvisual="false"/>
  </mujoco>
  <link
    name="base_link">
    <inertial>
      <origin
        xyz="0.00106636629393505 -0.0293070547501314 -0.0202271384386062"
        rpy="0 0 0" />
      <mass
        value="1" />
      <inertia
        ixx="0.003"
        ixy="0"
        ixz="0"
        iyy="0.004"
        iyz="-0.001"
        izz="0.002" />
    </inertial>
    <visual>
      <origin
        xyz="0 0 0"
        rpy="0 0 0" />
      <geometry>
        <mesh
          filename="../meshes/base_link.STL" />
      </geometry>
      <material
        name="">
        <color
          rgba="1 1 1 1" />
      </material>
    </visual>
    <collision>
      <origin
        xyz="0 0 0"
        rpy="0 0 0" />
      <geometry>
        <mesh
          filename="../meshes/base_link.STL" />
      </geometry>
    </collision>
  </link>
  <link
    name="link0">
    <inertial>
      <origin
        xyz="0.0111890887322725 7.95670400899548E-05 0.0214102523586093"
        rpy="0 0 0" />
      <mass
        value="3.3" />
      <inertia
        ixx="0.024"
        ixy="0.003"
        ixz="0.004"
        iyy="0.15"
        iyz="0.007"
        izz="0.144" />
    </inertial>
    <visual>
      <origin
        xyz="0 0 0"
        rpy="0 0 0" />
      <geometry>
        <mesh
          filename="../meshes/link0.STL" />
      </geometry>
      <material
        name="">
        <color
          rgba="1 1 1 1" />
      </material>
    </visual>
    <collision>
      <origin
        xyz="0 0 0"
        rpy="0 0 0" />
      <geometry>
        <mesh
          filename="../meshes/link0.STL" />
      </geometry>
    </collision>
  </link>
  <joint
    name="joint0"
    type="revolute">
    <origin
      xyz="0.00106821443596945 -0.0292999484608107 0.00800400717471925"
      rpy="0 0 0" />
    <parent
      link="base_link" />
    <child
      link="link0" />
    <axis
      xyz="0 0 -1" />
    <limit
      lower="-3.14"
      upper="3.14"
      effort="0"
      velocity="0" />
  </joint>
  <link
    name="link1">
    <inertial>
      <origin
        xyz="0.00281617747478818 0.0187461142617349 0.0803848783888099"
        rpy="0 0 0" />
      <mass
        value="2.2" />
      <inertia
        ixx="0.004"
        ixy="0.00"
        ixz="0.00"
        iyy="0.146"
        iyz="0.00"
        izz="0.163" />
    </inertial>
    <visual>
      <origin
        xyz="0 0 0"
        rpy="0 0 0" />
      <geometry>
        <mesh
          filename="../meshes/link1.STL" />
      </geometry>
      <material
        name="">
        <color
          rgba="1 1 1 1" />
      </material>
    </visual>
    <collision>
      <origin
        xyz="0 0 0"
        rpy="0 0 0" />
      <geometry>
        <mesh
          filename="../meshes/link1.STL" />
      </geometry>
    </collision>
  </link>
  <joint
    name="joint1"
    type="revolute">
    <origin
      xyz="0.25 0 -0.00150000000000016"
      rpy="0 0 0" />
    <parent
      link="link0" />
    <child
      link="link1" />
    <axis
      xyz="0 0 -1" />
    <limit
      lower="-2.5730"
      upper="2.5730"
      effort="0"
      velocity="0" />
  </joint>
  <link
    name="link2">
    <inertial>
      <origin
        xyz="0.190000000000004 -3.88578058618805E-16 0.00570000000000492"
        rpy="0 0 0" />
      <mass
        value="0.85" />
      <inertia
        ixx="0.043"
        ixy="0.002"
        ixz="-0.003"
        iyy="0.031"
        iyz="-0.006"
        izz="0.072" />
    </inertial>
    <visual>
      <origin
        xyz="0 0 0"
        rpy="0 0 0" />
      <geometry>
        <mesh
          filename="../meshes/link2.STL" />
      </geometry>
      <material
        name="">
        <color
          rgba="0.956862745098039 0.956862745098039 0.96078431372549 1" />
      </material>
    </visual>
    <collision>
      <origin
        xyz="0 0 0"
        rpy="0 0 0" />
      <geometry>
        <mesh
          filename="../meshes/link2.STL" />
      </geometry>
    </collision>
  </link>
  <joint
    name="joint2"
    type="revolute">
    <origin
      xyz="0 0.0612999999999991 0.0969999999999984"
      rpy="1.5707963267949 -0.870669676164259 3.14159265358979" />
    <parent
      link="link1" />
    <child
      link="link2" />
    <axis
      xyz="0 0 -1" />
    <limit
      lower="-2.0933"
      upper="0.7762"
      effort="0"
      velocity="0" />
  </joint>
  <link
    name="link3">
    <inertial>
      <origin
        xyz="0.062006399403465 -0.00325003674916025 0.0632250133882652"
        rpy="0 0 0" />
      <mass
        value="3" />
      <inertia
        ixx="0.241"
        ixy="-0.02"
        ixz="0.002"
        iyy="0.024"
        iyz="0.026"
        izz="0.246" />
    </inertial>
    <visual>
      <origin
        xyz="0 0 0"
        rpy="0 0 0" />
      <geometry>
        <mesh
          filename="../meshes/link3.STL" />
      </geometry>
      <material
        name="">
        <color
          rgba="1 1 1 1" />
      </material>
    </visual>
    <collision>
      <origin
        xyz="0 0 0"
        rpy="0 0 0" />
      <geometry>
        <mesh
          filename="../meshes/link3.STL" />
      </geometry>
    </collision>
  </link>
  <joint
    name="joint3"
    type="revolute">
    <origin
      xyz="0.380000000000003 0 -0.000800000000014886"
      rpy="-3.14159265358979 0 2.27092297742553" />
    <parent
      link="link2" />
    <child
      link="link3" />
    <axis
      xyz="0 0 1" />
    <limit
      lower="-0.7762"
      upper="1.0921"
      effort="0"
      velocity="0" />
  </joint>
  <link
    name="link4">
    <inertial>
      <origin
        xyz="-1.06914163189309E-07 -0.0450249174201101 0.217000395801011"
        rpy="0 0 0" />
      <mass
        value="1.7" />
      <inertia
        ixx="0.1"
        ixy="0.124"
        ixz="-0.007"
        iyy="0.155"
        iyz="-0.006"
        izz="0.254" />
    </inertial>
    <visual>
      <origin
        xyz="0 0 0"
        rpy="0 0 0" />
      <geometry>
        <mesh
          filename="../meshes/link4.STL" />
      </geometry>
      <material
        name="">
        <color
          rgba="0.956862745098039 0.956862745098039 0.96078431372549 1" />
      </material>
    </visual>
    <collision>
      <origin
        xyz="0 0 0"
        rpy="0 0 0" />
      <geometry>
        <mesh
          filename="../meshes/link4.STL" />
      </geometry>
    </collision>
  </link>
  <joint
    name="joint4"
    type="revolute">
    <origin
      xyz="0.170925093942183 -0.00673187074768322 0.0605000000000014"
      rpy="1.57079632679489 0 1.85877565337396" />
    <parent
      link="link3" />
    <child
      link="link4" />
    <axis
      xyz="0 0 1" />
    <limit
      lower="-3.14"
      upper="3.14"
      effort="0"
      velocity="0" />
  </joint>
  <link
    name="link5">
    <inertial>
      <origin
        xyz="0.00116772554274452 1.35911570886549E-09 0.00192542639535063"
        rpy="0 0 0" />
      <mass
        value="0.1" />
      <inertia
        ixx="0.006"
        ixy="0.007"
        ixz="0.001"
        iyy="0.009"
        iyz="0.001"
        izz="0.015" />
    </inertial>
    <visual>
      <origin
        xyz="0 0 0"
        rpy="0 0 0" />
      <geometry>
        <mesh
          filename="../meshes/link5.STL" />
      </geometry>
      <material
        name="">
        <color
          rgba="0.956862745098039 0.956862745098039 0.96078431372549 1" />
      </material>
    </visual>
    <collision>
      <origin
        xyz="0 0 0"
        rpy="0 0 0" />
      <geometry>
        <mesh
          filename="../meshes/link5.STL" />
      </geometry>
    </collision>
  </link>
  <joint
    name="joint5"
    type="revolute">
    <origin
      xyz="0 -0.00100000000001002 0.216999999999999"
      rpy="1.5707963267949 -1.5707963267949 0" />
    <parent
      link="link4" />
    <child
      link="link5" />
    <axis
      xyz="0 0 -1" />
    <limit
      lower="-1.57"
      upper="1.57"
      effort="0"
      velocity="0" />
  </joint>
  <link
    name="link6">
    <inertial>
      <origin
        xyz="-4.4203297064338E-09 7.20313475532919E-10 0.022185925556943"
        rpy="0 0 0" />
      <mass
        value="0.2" />
      <inertia
        ixx="0.012"
        ixy="0.00"
        ixz="0.00"
        iyy="0.021"
        iyz="0.00"
        izz="0.033" />
    </inertial>
    <visual>
      <origin
        xyz="0 0 0"
        rpy="0 0 0" />
      <geometry>
        <mesh
          filename="../meshes/link6.STL" />
      </geometry>
      <material
        name="">
        <color
          rgba="1 1 1 1" />
      </material>
    </visual>
    <collision>
      <origin
        xyz="0 0 0"
        rpy="0 0 0" />
      <geometry>
        <mesh
          filename="../meshes/link6.STL" />
      </geometry>
    </collision>
  </link>
  <joint
    name="joint6"
    type="revolute">
    <origin
      xyz="0 0 0"
      rpy="3.14159265358979 -1.5707963267949 0" />
    <parent
      link="link5" />
    <child
      link="link6" />
    <axis
      xyz="0 0 -1" />
    <limit
      lower="-3.14"
      upper="3.14"
      effort="0"
      velocity="0" />
  </joint>
</robot>
